Workbook

Sheet dynamic numbers
A1: Arena | B1: WR | D1: Placement | E1: Trophie destribution | G1: trophie ev | H1: =B3*E2+B3*E3+B3*E4+B3*E5 -> 20 | J1: Match Duration in Minutes
A2: arena 1 WR (bots) | B2: 1 | D2: 1st place | E2: 60 | J2: 0.5
A3: arena 2+ WR | B3: 0.25 | D3: 2nd place | E3: 35
D4: 3rd place | E4: 0
D5: 4th place | E5: -15

Sheet Arena progression
A1: Arena | B1: Trophy range | C1: min trophies | D1: max trophies | E1: Level Required | F1: Trophy Count | G1: Reward | H1: games to reach
A2: 1 | B2: 0-300 | C2: =IFERROR(__xludf.DUMMYFUNCTION("VALUE(REGEXEXTRACT(B2,""(\d[\d,]*)-""))"),0.0) -> 0 | D2: =IFERROR(__xludf.DUMMYFUNCTION("VALUE(REGEXEXTRACT(B2,""-(\d[\d,]*)""))"),300.0) -> 300 | E2: 1 | F2: 50 | H2: =F2/'dynamic numbers'!$E$2 -> 0.83333333 | J2: =CONCATENATE(C2,"-",D2) -> 0-300
F3: 100 | H3: =F3/'dynamic numbers'!$E$2 -> 1.6666667
F4: 150 | H4: =F4/'dynamic numbers'!$E$2 -> 2.5
F5: 200 | H5: =F5/'dynamic numbers'!$E$2 -> 3.3333333
F6: 250 | H6: =F6/'dynamic numbers'!$E$2 -> 4.1666667
A7: =1+A2 -> 2 | B7: 301-600 | C7: =D2+1 -> 301 | D7: =IFERROR(__xludf.DUMMYFUNCTION("VALUE(REGEXEXTRACT(B7,""-(\d[\d,]*)""))"),600.0) -> 600 | E7: 2 | F7: 325 | H7: =F7/'dynamic numbers'!$H$1 -> 16.25
F8: 400 | H8: =F8/'dynamic numbers'!$H$1 -> 20
F9: 450 | H9: =F9/'dynamic numbers'!$H$1 -> 22.5
F10: 500 | H10: =F10/'dynamic numbers'!$H$1 -> 25
F11: 550 | H11: =F11/'dynamic numbers'!$H$1 -> 27.5
A12: =1+A7 -> 3 | B12: 601-1000 | C12: =D7+1 -> 601 | D12: =IFERROR(__xludf.DUMMYFUNCTION("VALUE(REGEXEXTRACT(B12,""-(\d[\d,]*)""))"),1000.0) -> 1000 | E12: 3 | F12: 625 | H12: =F12/'dynamic numbers'!$H$1 -> 31.25
F13: 700 | H13: =F13/'dynamic numbers'!$H$1 -> 35
F14: 750 | H14: =F14/'dynamic numbers'!$H$1 -> 37.5
F15: 800 | H15: =F15/'dynamic numbers'!$H$1 -> 40
F16: 850 | H16: =F16/'dynamic numbers'!$H$1 -> 42.5
F17: 900 | H17: =F17/'dynamic numbers'!$H$1 -> 45
F18: 950 | H18: =F18/'dynamic numbers'!$H$1 -> 47.5
A19: =A12+1 -> 4 | B19: 1001-1300 | C19: =D12+1 -> 1001 | D19: =IFERROR(__xludf.DUMMYFUNCTION("VALUE(REGEXEXTRACT(B19,""-(\d[\d,]*)""))"),1300.0) -> 1300 | E19: 4 | F19: 1025 | H19: =F19/'dynamic numbers'!$H$1 -> 51.25
F20: 1100 | H20: =F20/'dynamic numbers'!$H$1 -> 55
F21: 1150 | H21: =F21/'dynamic numbers'!$H$1 -> 57.5
F22: 1200 | H22: =F22/'dynamic numbers'!$H$1 -> 60
F23: 1250 | H23: =F23/'dynamic numbers'!$H$1 -> 62.5
A24: =1+A19 -> 5 | B24: 1301-1600 | C24: =D19+1 -> 1301 | D24: =IFERROR(__xludf.DUMMYFUNCTION("VALUE(REGEXEXTRACT(B24,""-(\d[\d,]*)""))"),1600.0) -> 1600 | E24: 5 | F24: 1325 | H24: =F24/'dynamic numbers'!$H$1 -> 66.25
F25: 1400 | H25: =F25/'dynamic numbers'!$H$1 -> 70
F26: 1450 | H26: =F26/'dynamic numbers'!$H$1 -> 72.5
F27: 1500 | H27: =F27/'dynamic numbers'!$H$1 -> 75
F28: 1550 | H28: =F28/'dynamic numbers'!$H$1 -> 77.5
A29: =1+A24 -> 6 | B29: 1601-2000 | C29: =D24+1 -> 1601 | D29: =IFERROR(__xludf.DUMMYFUNCTION("VALUE(REGEXEXTRACT(B29,""-(\d[\d,]*)""))"),2000.0) -> 2000 | E29: 6 | F29: 1625 | H29: =F29/'dynamic numbers'!$H$1 -> 81.25
F30: 1700 | H30: =F30/'dynamic numbers'!$H$1 -> 85
F31: 1750 | H31: =F31/'dynamic numbers'!$H$1 -> 87.5
F32: 1800 | H32: =F32/'dynamic numbers'!$H$1 -> 90
F33: 1850 | H33: =F33/'dynamic numbers'!$H$1 -> 92.5
F34: 1900 | H34: =F34/'dynamic numbers'!$H$1 -> 95
F35: 1950 | H35: =F35/'dynamic numbers'!$H$1 -> 97.5
A36: 7 | B36: 2001-2300 | C36: =D29+1 -> 2001 | D36: =IFERROR(__xludf.DUMMYFUNCTION("VALUE(REGEXEXTRACT(B36,""-(\d[\d,]*)""))"),2300.0) -> 2300 | E36: 8 | F36: 2025 | H36: =F36/'dynamic numbers'!$H$1 -> 101.25
F37: 2100 | H37: =F37/'dynamic numbers'!$H$1 -> 105
F38: 2150 | H38: =F38/'dynamic numbers'!$H$1 -> 107.5
F39: 2200 | H39: =F39/'dynamic numbers'!$H$1 -> 110
F40: 2250 | H40: =F40/'dynamic numbers'!$H$1 -> 112.5
...

Sheet Arena Progress Option 2
A1: Arena | B1: min trophies | C1: max trophies | D1: Level | E1: Trophy Count | F1: Reward | G1: Reward Amount | H1: Reward | I1: Reward Amount | J1: Reward | K1: Reward Amount | L1: Matches Required | M1: Cumulative Matches to Reach | N1: Net Playtime to Reach | O1: Gross Playtime to Reach
A2: Lost Oasis | E2: 0
A3: Lost Oasis | B3: =MINIFS(E$3:E$27, D$3:D$27, D3) -> 10 | C3: =MAXIFS(E$3:E$27, D$3:D$27, D3) -> 100 | D3: 1 | E3: 10 | F3: Coins | G3: 50 | L3: =M3 -> 0.5 | M3: =E3/'dynamic numbers'!$H$1 -> 0.5 | N3: =ROUNDUP(M3*'dynamic numbers'!$J$2,0) -> 1 | O3: =N3*1.3 -> 1.3
A4: Lost Oasis | B4: =MINIFS(E$3:E$27, D$3:D$27, D4) -> 10 | C4: =MAXIFS(E$3:E$27, D$3:D$27, D4) -> 100 | D4: 1 | E4: 25 | F4: Upgrade_Cards | G4: 5 | L4: =M4-M3 -> 0.75 | M4: =E4/'dynamic numbers'!$H$1 -> 1.25 | N4: =ROUNDUP(M4*'dynamic numbers'!$J$2,0) -> 1 | O4: =N4*1.3 -> 1.3
A5: Lost Oasis | B5: =MINIFS(E$3:E$27, D$3:D$27, D5) -> 10 | C5: =MAXIFS(E$3:E$27, D$3:D$27, D5) -> 100 | D5: 1 | E5: 50 | F5: Coins | G5: 75 | L5: =M5-M4 -> 1.25 | M5: =E5/'dynamic numbers'!$H$1 -> 2.5 | N5: =ROUNDUP(M5*'dynamic numbers'!$J$2,0) -> 2 | O5: =N5*1.3 -> 2.6
A6: Lost Oasis | B6: =MINIFS(E$3:E$27, D$3:D$27, D6) -> 10 | C6: =MAXIFS(E$3:E$27, D$3:D$27, D6) -> 100 | D6: 1 | E6: 75 | F6: Upgrade_Cards | G6: 10 | L6: =M6-M5 -> 1.25 | M6: =E6/'dynamic numbers'!$H$1 -> 3.75 | N6: =ROUNDUP(M6*'dynamic numbers'!$J$2,0) -> 2 | O6: =N6*1.3 -> 2.6
A7: Lost Oasis | B7: =MINIFS(E$3:E$27, D$3:D$27, D7) -> 10 | C7: =MAXIFS(E$3:E$27, D$3:D$27, D7) -> 100 | D7: 1 | E7: 100 | F7: Coins | G7: 100 | L7: =M7-M6 -> 1.25 | M7: =E7/'dynamic numbers'!$H$1 -> 5 | N7: =ROUNDUP(M7*'dynamic numbers'!$J$2,0) -> 3 | O7: =N7*1.3 -> 3.9
A8: Mystic Forest | B8: =MINIFS(E$3:E$27, D$3:D$27, D8) -> 250 | C8: =MAXIFS(E$3:E$27, D$3:D$27, D8) -> 750 | D8: 2 | E8: 250 | F8: Arena_Mystic_Forest | H8: Hero_Glint | L8: =M8-M7 -> 7.5 | M8: =E8/'dynamic numbers'!$H$1 -> 12.5 | N8: =ROUNDUP(M8*'dynamic numbers'!$J$2,0) -> 7 | O8: =N8*1.3 -> 9.1
A9: Mystic Forest | B9: =MINIFS(E$3:E$27, D$3:D$27, D9) -> 250 | C9: =MAXIFS(E$3:E$27, D$3:D$27, D9) -> 750 | D9: 2 | E9: 350 | F9: Coins | G9: 125 | L9: =M9-M8 -> 5 | M9: =E9/'dynamic numbers'!$H$1 -> 17.5 | N9: =ROUNDUP(M9*'dynamic numbers'!$J$2,0) -> 9 | O9: =N9*1.3 -> 11.7
A10: Mystic Forest | B10: =MINIFS(E$3:E$27, D$3:D$27, D10) -> 250 | C10: =MAXIFS(E$3:E$27, D$3:D$27, D10) -> 750 | D10: 2 | E10: 500 | F10: Upgrade_Cards | G10: 15 | L10: =M10-M9 -> 7.5 | M10: =E10/'dynamic numbers'!$H$1 -> 25 | N10: =ROUNDUP(M10*'dynamic numbers'!$J$2,0) -> 13 | O10: =N10*1.3 -> 16.9
A11: Mystic Forest | B11: =MINIFS(E$3:E$27, D$3:D$27, D11) -> 250 | C11: =MAXIFS(E$3:E$27, D$3:D$27, D11) -> 750 | D11: 2 | E11: 550 | F11: Coins | G11: 150 | L11: =M11-M10 -> 2.5 | M11: =E11/'dynamic numbers'!$H$1 -> 27.5 | N11: =ROUNDUP(M11*'dynamic numbers'!$J$2,0) -> 14 | O11: =N11*1.3 -> 18.2
A12: Mystic Forest | B12: =MINIFS(E$3:E$27, D$3:D$27, D12) -> 250 | C12: =MAXIFS(E$3:E$27, D$3:D$27, D12) -> 750 | D12: 2 | E12: 600 | F12: Upgrade_Cards | G12: 20 | L12: =M12-M11 -> 2.5 | M12: =E12/'dynamic numbers'!$H$1 -> 30 | N12: =ROUNDUP(M12*'dynamic numbers'!$J$2,0) -> 15 | O12: =N12*1.3 -> 19.5
A13: Mystic Forest | B13: =MINIFS(E$3:E$27, D$3:D$27, D13) -> 250 | C13: =MAXIFS(E$3:E$27, D$3:D$27, D13) -> 750 | D13: 2 | E13: 700 | F13: Coins | G13: 175 | L13: =M13-M12 -> 5 | M13: =E13/'dynamic numbers'!$H$1 -> 35 | N13: =ROUNDUP(M13*'dynamic numbers'!$J$2,0) -> 18 | O13: =N13*1.3 -> 23.4
A14: Mystic Forest | B14: =MINIFS(E$3:E$27, D$3:D$27, D14) -> 250 | C14: =MAXIFS(E$3:E$27, D$3:D$27, D14) -> 750 | D14: 2 | E14: 750 | F14: Upgrade_Cards | G14: 25 | L14: =M14-M13 -> 2.5 | M14: =E14/'dynamic numbers'!$H$1 -> 37.5 | N14: =ROUNDUP(M14*'dynamic numbers'!$J$2,0) -> 19 | O14: =N14*1.3 -> 24.7
A15: Sakura Cliffs | B15: =MINIFS(E$3:E$27, D$3:D$27, D15) -> 1500 | C15: =MAXIFS(E$3:E$27, D$3:D$27, D15) -> 3500 | D15: 3 | E15: 1500 | F15: Arena_Sakura_Cliffs | H15: Hero_Cinder | L15: =M15-M14 -> 37.5 | M15: =E15/'dynamic numbers'!$H$1 -> 75 | N15: =ROUNDUP(M15*'dynamic numbers'!$J$2,0) -> 38 | O15: =N15*1.3 -> 49.4
A16: Sakura Cliffs | B16: =MINIFS(E$3:E$27, D$3:D$27, D16) -> 1500 | C16: =MAXIFS(E$3:E$27, D$3:D$27, D16) -> 3500 | D16: 3 | E16: 1600 | F16: Coins | G16: 200 | L16: =M16-M15 -> 5 | M16: =E16/'dynamic numbers'!$H$1 -> 80 | N16: =ROUNDUP(M16*'dynamic numbers'!$J$2,0) -> 40 | O16: =N16*1.3 -> 52
A17: Sakura Cliffs | B17: =MINIFS(E$3:E$27, D$3:D$27, D17) -> 1500 | C17: =MAXIFS(E$3:E$27, D$3:D$27, D17) -> 3500 | D17: 3 | E17: 1750 | F17: Upgrade_Cards | G17: 30 | L17: =M17-M16 -> 7.5 | M17: =E17/'dynamic numbers'!$H$1 -> 87.5 | N17: =ROUNDUP(M17*'dynamic numbers'!$J$2,0) -> 44 | O17: =N17*1.3 -> 57.2
A18: Sakura Cliffs | B18: =MINIFS(E$3:E$27, D$3:D$27, D18) -> 1500 | C18: =MAXIFS(E$3:E$27, D$3:D$27, D18) -> 3500 | D18: 3 | E18: 1900 | F18: Coins | G18: 225 | L18: =M18-M17 -> 7.5 | M18: =E18/'dynamic numbers'!$H$1 -> 95 | N18: =ROUNDUP(M18*'dynamic numbers'!$J$2,0) -> 48 | O18: =N18*1.3 -> 62.4
A19: Sakura Cliffs | B19: =MINIFS(E$3:E$27, D$3:D$27, D19) -> 1500 | C19: =MAXIFS(E$3:E$27, D$3:D$27, D19) -> 3500 | D19: 3 | E19: 2000 | F19: Upgrade_Cards | G19: 35 | L19: =M19-M18 -> 5 | M19: =E19/'dynamic numbers'!$H$1 -> 100 | N19: =ROUNDUP(M19*'dynamic numbers'!$J$2,0) -> 50 | O19: =N19*1.3 -> 65
A20: Sakura Cliffs | B20: =MINIFS(E$3:E$27, D$3:D$27, D20) -> 1500 | C20: =MAXIFS(E$3:E$27, D$3:D$27, D20) -> 3500 | D20: 3 | E20: 2250 | F20: Coins | G20: 250 | L20: =M20-M19 -> 12.5 | M20: =E20/'dynamic numbers'!$H$1 -> 112.5 | N20: =ROUNDUP(M20*'dynamic numbers'!$J$2,0) -> 57 | O20: =N20*1.3 -> 74.1
A21: Sakura Cliffs | B21: =MINIFS(E$3:E$27, D$3:D$27, D21) -> 1500 | C21: =MAXIFS(E$3:E$27, D$3:D$27, D21) -> 3500 | D21: 3 | E21: 2500 | F21: Upgrade_Cards | G21: 40 | L21: =M21-M20 -> 12.5 | M21: =E21/'dynamic numbers'!$H$1 -> 125 | N21: =ROUNDUP(M21*'dynamic numbers'!$J$2,0) -> 63 | O21: =N21*1.3 -> 81.9
A22: Sakura Cliffs | B22: =MINIFS(E$3:E$27, D$3:D$27, D22) -> 1500 | C22: =MAXIFS(E$3:E$27, D$3:D$27, D22) -> 3500 | D22: 3 | E22: 2600 | F22: Coins | G22: 350 | L22: =M22-M21 -> 5 | M22: =E22/'dynamic numbers'!$H$1 -> 130 | N22: =ROUNDUP(M22*'dynamic numbers'!$J$2,0) -> 65 | O22: =N22*1.3 -> 84.5
A23: Sakura Cliffs | B23: =MINIFS(E$3:E$27, D$3:D$27, D23) -> 1500 | C23: =MAXIFS(E$3:E$27, D$3:D$27, D23) -> 3500 | D23: 3 | E23: 2750 | F23: Upgrade_Cards | G23: 50 | L23: =M23-M22 -> 7.5 | M23: =E23/'dynamic numbers'!$H$1 -> 137.5 | N23: =ROUNDUP(M23*'dynamic numbers'!$J$2,0) -> 69 | O23: =N23*1.3 -> 89.7
A24: Sakura Cliffs | B24: =MINIFS(E$3:E$27, D$3:D$27, D24) -> 1500 | C24: =MAXIFS(E$3:E$27, D$3:D$27, D24) -> 3500 | D24: 3 | E24: 2900 | F24: Coins | G24: 500 | L24: =M24-M23 -> 7.5 | M24: =E24/'dynamic numbers'!$H$1 -> 145 | N24: =ROUNDUP(M24*'dynamic numbers'!$J$2,0) -> 73 | O24: =N24*1.3 -> 94.9
A25: Sakura Cliffs | B25: =MINIFS(E$3:E$27, D$3:D$27, D25) -> 1500 | C25: =MAXIFS(E$3:E$27, D$3:D$27, D25) -> 3500 | D25: 3 | E25: 3000 | F25: Upgrade_Cards | G25: 75 | L25: =M25-M24 -> 5 | M25: =E25/'dynamic numbers'!$H$1 -> 150 | N25: =ROUNDUP(M25*'dynamic numbers'!$J$2,0) -> 75 | O25: =N25*1.3 -> 97.5
A26: Sakura Cliffs | B26: =MINIFS(E$3:E$27, D$3:D$27, D26) -> 1500 | C26: =MAXIFS(E$3:E$27, D$3:D$27, D26) -> 3500 | D26: 3 | E26: 3250 | F26: Coins | G26: 750 | L26: =M26-M25 -> 12.5 | M26: =E26/'dynamic numbers'!$H$1 -> 162.5 | N26: =ROUNDUP(M26*'dynamic numbers'!$J$2,0) -> 82 | O26: =N26*1.3 -> 106.6
A27: Sakura Cliffs | B27: =MINIFS(E$3:E$27, D$3:D$27, D27) -> 1500 | C27: =MAXIFS(E$3:E$27, D$3:D$27, D27) -> 3500 | D27: 3 | E27: 3500 | F27: Upgrade_Cards | G27: 100 | L27: =M27-M26 -> 12.5 | M27: =E27/'dynamic numbers'!$H$1 -> 175 | N27: =ROUNDUP(M27*'dynamic numbers'!$J$2,0) -> 88 | O27: =N27*1.3 -> 114.4

Sheet Arenas
A1: Arena Name | B1: ArenaID
A2: Lost Oasis | B2: arena.lostoasis
A3: Mystic Forest | B3: arena.mysticforest
A4: Sakura Cliffs | B4: arena.sakuracliffs

Sheet Rewards
A1: RewardName | B1: RewardID
A2: Coins | B2: reward.currency.coins
A3: Upgrade_Cards | B3: reward.currency.cards
A4: Arena_Mystic_Forest | B4: reward.arena.mysticforest
A5: Arena_Sakura_Cliffs | B5: reward.arena.sakuracliffs
A6: Hero_Glint | B6: reward.hero.glint
A7: Hero_Cliff | B7: reward.hero.cliff
A8: Hero_Cinder | B8: reward.hero.cinder
A9: Hero_Tank | B9: reward.hero.tank
A10: Hero_Pedro | B10: reward.hero.pedro
A11: Hero_Flick | B11: reward.hero.flick
A12: Hero_Guy | B12: reward.hero.guy

Sheet Seasonal progression
A1: Arena | B1: Trophy range | C1: min trophies | D1: max trophies | E1: Trophy Count | F1: Reward | G1: games to reach total | H1: games to reach from seasonal
A2: Seasonal 1 | B2: =CONCATENATE(C2,"-",D2) -> 14001-15000 | C2: 14001 | D2: 15000 | E2: 14050 | G2: =E2/'dynamic numbers'!$H$1 -> 702.5 | H2: =(E2-14000)/'dynamic numbers'!$H$1 -> 2.5
E3: 14250 | G3: =E3/'dynamic numbers'!$H$1 -> 712.5 | H3: =(E3-14000)/'dynamic numbers'!$H$1 -> 12.5
E4: 14450 | G4: =E4/'dynamic numbers'!$H$1 -> 722.5 | H4: =(E4-14000)/'dynamic numbers'!$H$1 -> 22.5
E5: 14650 | G5: =E5/'dynamic numbers'!$H$1 -> 732.5 | H5: =(E5-14000)/'dynamic numbers'!$H$1 -> 32.5
E6: 14900 | G6: =E6/'dynamic numbers'!$H$1 -> 745 | H6: =(E6-14000)/'dynamic numbers'!$H$1 -> 45
A7: Seasonal 2 | B7: =CONCATENATE(C7,"-",D7) -> 15001-16000 | C7: =D2+1 -> 15001 | D7: 16000 | E7: 15050 | G7: =E7/'dynamic numbers'!$H$1 -> 752.5 | H7: =(E7-14000)/'dynamic numbers'!$H$1 -> 52.5
E8: 15250 | G8: =E8/'dynamic numbers'!$H$1 -> 762.5 | H8: =(E8-14000)/'dynamic numbers'!$H$1 -> 62.5
E9: 15450 | G9: =E9/'dynamic numbers'!$H$1 -> 772.5 | H9: =(E9-14000)/'dynamic numbers'!$H$1 -> 72.5
E10: 15650 | G10: =E10/'dynamic numbers'!$H$1 -> 782.5 | H10: =(E10-14000)/'dynamic numbers'!$H$1 -> 82.5
E11: 15900 | G11: =E11/'dynamic numbers'!$H$1 -> 795 | H11: =(E11-14000)/'dynamic numbers'!$H$1 -> 95
A12: Seasonal 3 | B12: =CONCATENATE(C12,"-",D12) -> 16001-17500 | C12: =D7+1 -> 16001 | D12: 17500 | E12: 16100 | G12: =E12/'dynamic numbers'!$H$1 -> 805 | H12: =(E12-14000)/'dynamic numbers'!$H$1 -> 105
E13: 16300 | G13: =E13/'dynamic numbers'!$H$1 -> 815 | H13: =(E13-14000)/'dynamic numbers'!$H$1 -> 115
E14: 16550 | G14: =E14/'dynamic numbers'!$H$1 -> 827.5 | H14: =(E14-14000)/'dynamic numbers'!$H$1 -> 127.5
E15: 16750 | G15: =E15/'dynamic numbers'!$H$1 -> 837.5 | H15: =(E15-14000)/'dynamic numbers'!$H$1 -> 137.5
E16: 16950 | G16: =E16/'dynamic numbers'!$H$1 -> 847.5 | H16: =(E16-14000)/'dynamic numbers'!$H$1 -> 147.5
E17: 17200 | G17: =E17/'dynamic numbers'!$H$1 -> 860 | H17: =(E17-14000)/'dynamic numbers'!$H$1 -> 160
E18: 17400 | G18: =E18/'dynamic numbers'!$H$1 -> 870 | H18: =(E18-14000)/'dynamic numbers'!$H$1 -> 170
A19: Seasonal 4 | B19: =CONCATENATE(C19,"-",D19) -> 17501-999999 | C19: 17501 | D19: 999999 | E19: 17600 | G19: =E19/'dynamic numbers'!$H$1 -> 880 | H19: =(E19-14000)/'dynamic numbers'!$H$1 -> 180
E20: 17800 | G20: =E20/'dynamic numbers'!$H$1 -> 890 | H20: =(E20-14000)/'dynamic numbers'!$H$1 -> 190
E21: 18050 | G21: =E21/'dynamic numbers'!$H$1 -> 902.5 | H21: =(E21-14000)/'dynamic numbers'!$H$1 -> 202.5
E22: 18250 | G22: =E22/'dynamic numbers'!$H$1 -> 912.5 | H22: =(E22-14000)/'dynamic numbers'!$H$1 -> 212.5
E23: 18450 | G23: =E23/'dynamic numbers'!$H$1 -> 922.5 | H23: =(E23-14000)/'dynamic numbers'!$H$1 -> 222.5
E24: 18700 | G24: =E24/'dynamic numbers'!$H$1 -> 935 | H24: =(E24-14000)/'dynamic numbers'!$H$1 -> 235
E25: 18900 | G25: =E25/'dynamic numbers'!$H$1 -> 945 | H25: =(E25-14000)/'dynamic numbers'!$H$1 -> 245
